CMSSW_11_2_4: No such file or directory.
/afs/cern.ch/user/m/malvesga/.local/lib/python3.8/site-packages/numpy/core/getlimits.py:499: UserWarning: The value of the smallest subnormal for <class 'numpy.float32'> type is zero.
  setattr(self, word, getattr(machar, word).flat[0])
/afs/cern.ch/user/m/malvesga/.local/lib/python3.8/site-packages/numpy/core/getlimits.py:89: UserWarning: The value of the smallest subnormal for <class 'numpy.float32'> type is zero.
  return self._float_to_str(self.smallest_subnormal)
/afs/cern.ch/user/m/malvesga/.local/lib/python3.8/site-packages/numpy/core/getlimits.py:499: UserWarning: The value of the smallest subnormal for <class 'numpy.float64'> type is zero.
  setattr(self, word, getattr(machar, word).flat[0])
/afs/cern.ch/user/m/malvesga/.local/lib/python3.8/site-packages/numpy/core/getlimits.py:89: UserWarning: The value of the smallest subnormal for <class 'numpy.float64'> type is zero.
  return self._float_to_str(self.smallest_subnormal)
Traceback (most recent call last):
  File "/afs/cern.ch/work/m/malvesga/ProtonRecon/TEST/CMSSW_11_2_4/src/workspace/pps-ww-analysis-notebook/process_data_random_protons.py", line 114, in <module>
    process_data_random_protons_( apply_fiducial=True, within_aperture=True, select_2protons=True, runMin=runMin_, runMax=runMax_ )
  File "/afs/cern.ch/work/m/malvesga/ProtonRecon/TEST/CMSSW_11_2_4/src/workspace/pps-ww-analysis-notebook/ProcessData.py", line 403, in __call__
    with pd.HDFStore( file_path_, 'w', complevel=5 ) as store_:
  File "/afs/cern.ch/user/m/malvesga/.local/lib/python3.8/site-packages/pandas/io/pytables.py", line 591, in __init__
    self.open(mode=mode, **kwargs)
  File "/afs/cern.ch/user/m/malvesga/.local/lib/python3.8/site-packages/pandas/io/pytables.py", line 740, in open
    self._handle = tables.open_file(self._path, self._mode, **kwargs)
  File "/afs/cern.ch/user/m/malvesga/.local/lib/python3.8/site-packages/tables/file.py", line 300, in open_file
    return File(filename, mode, title, root_uep, filters, **kwargs)
  File "/afs/cern.ch/user/m/malvesga/.local/lib/python3.8/site-packages/tables/file.py", line 750, in __init__
    self._g_new(filename, mode, **params)
  File "tables/hdf5extension.pyx", line 368, in tables.hdf5extension.File._g_new
  File "/afs/cern.ch/user/m/malvesga/.local/lib/python3.8/site-packages/tables/utils.py", line 157, in check_file_access
    raise OSError(f"``{path.parent}`` does not exist")
OSError: ``/pool/condor/dir_45314/i/eos/home-m/malvesga/SWAN_projects/Antonio_UL/output`` does not exist
cp: No match.
